<?xml version="1.0" encoding="utf-8"?>
<robot
  name="mirobot" xmlns:xacro="http://ros.org/wiki/xacro">
  <link name="world" >
  </link>
  <joint
    name="fixed_base"
    type="fixed">
    <origin
      xyz="0 0 0"
      rpy="0 0 0" />
    <parent
      link="world" />
    <child
      link="base_link" />
    <axis
      xyz="0 0 1" />
  </joint>
  <link
    name="base_link">
    <inertial>
      <origin
        xyz="0.00072554 2.2065E-05 0.024268"
        rpy="0 0 0" />
      <mass
        value="0.1" />
      <inertia
        ixx="0.001"
        ixy="0"
        ixz="0"
        iyy="0.001"
        iyz="0"
        izz="0.001" />
    </inertial>
    <visual>
      <origin
        xyz="0 0 0"
        rpy="0 0 0" />
      <geometry>
        <mesh
          filename="mirobot/base_link.STL" />
      </geometry>
      <material
        name="">
        <color
          rgba="0.44 0.5 0.56 1" />
      </material>
    </visual>
    <collision>
      <origin
        xyz="0 0 0"
        rpy="0 0 0" />
      <geometry>
        <mesh
          filename="mirobot/base_link.STL" />
      </geometry>
    </collision>
  </link>
  <link
    name="Link1">
    <inertial>
      <origin
        xyz="0.011601 0.022341 0.044136"
        rpy="0 0 0" />
      <mass
        value="0.1" />
      <inertia
        ixx="0.001"
        ixy="0"
        ixz="0"
        iyy="0.001"
        iyz="0"
        izz="0.001" />
    </inertial>
    <visual>
      <origin
        xyz="0 0 0"
        rpy="0 0 0" />
      <geometry>
        <mesh
          filename="mirobot/Link1.STL" />
      </geometry>
      <material
        name="">
        <color
          rgba="0.83 0.83 0.83 1" />
      </material>
    </visual>
    <collision>
      <origin
        xyz="0 0 0"
        rpy="0 0 0" />
      <geometry>
        <mesh
          filename="mirobot/Link1.STL" />
      </geometry>
    </collision>
  </link>
  <joint
    name="joint1"
    type="revolute">
    <origin
      xyz="0 0 0.065406"
      rpy="0 0 0" />
    <parent
      link="base_link" />
    <child
      link="Link1" />
    <axis
      xyz="0 0 1" />
    <limit
      lower="-1.7453"
      upper="2.7925"
      effort="1"
      velocity="0.7" />
  </joint>
  <link
    name="Link2">
    <inertial>
      <origin
        xyz="0.054694 0.0036383 -0.0056108"
        rpy="0 0 0" />
      <mass
        value="0.05" />
      <inertia
        ixx="0.001"
        ixy="0"
        ixz="0"
        iyy="0.001"
        iyz="0"
        izz="0.001" />
    </inertial>
    <visual>
      <origin
        xyz="0 0 0"
        rpy="0 0 0" />
      <geometry>
        <mesh
          filename="mirobot/Link2.STL" />
      </geometry>
      <material
        name="">
        <color
          rgba="1 0.65 0 1" />
      </material>
    </visual>
    <collision>
      <origin
        xyz="0 0 0"
        rpy="0 0 0" />
      <geometry>
        <mesh
          filename="mirobot/Link2.STL" />
      </geometry>
    </collision>
  </link>
  <joint
    name="joint2"
    type="revolute">
    <origin
      xyz="0.029687 -0.022 0.061593"
      rpy="3.1402 -1.5708 1.5722" />
    <parent
      link="Link1" />
    <child
      link="Link2" />
    <axis
      xyz="0 0 1" />
    <limit
      lower="-0.5235"
      upper="1.2217"
      effort="1"
      velocity="0.7" />
  </joint>
  <link
    name="Link3">
    <inertial>
      <origin
        xyz="0.0099997 0.0071403 0.037517"
        rpy="0 0 0" />
      <mass
        value="0.05" />
      <inertia
        ixx="0.001"
        ixy="0"
        ixz="0"
        iyy="0.001"
        iyz="0"
        izz="0.001" />
    </inertial>
    <visual>
      <origin
        xyz="0 0 0"
        rpy="0 0 0" />
      <geometry>
        <mesh
          filename="mirobot/Link3.STL" />
      </geometry>
      <material
        name="">
        <color
          rgba="0.83 0.83 0.83 1" />
      </material>
    </visual>
    <collision>
      <origin
        xyz="0 0 0"
        rpy="0 0 0" />
      <geometry>
        <mesh
          filename="mirobot/Link3.STL" />
      </geometry>
    </collision>
  </link>
  <joint
    name="joint3"
    type="revolute">
    <origin
      xyz="0.108 0 -0.0094471"
      rpy="0 0 0" />
    <parent
      link="Link2" />
    <child
      link="Link3" />
    <axis
      xyz="0 0 1" />
    <limit
      lower="-2.9671"
      upper="1.0472"
      effort="1"
      velocity="0.4" />
  </joint>
  <link
    name="Link4">
    <inertial>
      <origin
        xyz="-8.0804E-06 0.0043797 0.040569"
        rpy="0 0 0" />
      <mass
        value="0.03" />
      <inertia
        ixx="0.001"
        ixy="0"
        ixz="0"
        iyy="0.001"
        iyz="0"
        izz="0.001" />
    </inertial>
    <visual>
      <origin
        xyz="0 0 0"
        rpy="0 0 0" />
      <geometry>
        <mesh
          filename="mirobot/Link4.STL" />
      </geometry>
      <material
        name="">
        <color
          rgba="1 0.65 0 1" />
      </material>
    </visual>
    <collision>
      <origin
        xyz="0 0 0"
        rpy="0 0 0" />
      <geometry>
        <mesh
          filename="mirobot/Link4.STL" />
      </geometry>
    </collision>
  </link>
  <joint
    name="joint4"
    type="revolute">
    <origin
      xyz="0.020001 0.10743 0.031439"
      rpy="-1.5708 0 0" />
    <parent
      link="Link3" />
    <child
      link="Link4" />
    <axis
      xyz="0 0 1" />
    <limit
      lower="-6.1086"
      upper="6.1086"
      effort="1"
      velocity="0.8" />
  </joint>
  <link
    name="Link5">
    <inertial>
      <origin
        xyz="0.00025302 -0.0020133 0.010352"
        rpy="0 0 0" />
      <mass
        value="0.03" />
      <inertia
        ixx="0.001"
        ixy="0"
        ixz="0"
        iyy="0.001"
        iyz="0"
        izz="0.001" />
    </inertial>
    <visual>
      <origin
        xyz="0 0 0"
        rpy="0 0 0" />
      <geometry>
        <mesh
          filename="mirobot/Link5.STL" />
      </geometry>
      <material
        name="">
        <color
          rgba="0.44 0.5 0.56 1" />
      </material>
    </visual>
    <collision>
      <origin
        xyz="0 0 0"
        rpy="0 0 0" />
      <geometry>
        <mesh
          filename="mirobot/Link5.STL" />
      </geometry>
    </collision>
  </link>
  <joint
    name="joint5"
    type="revolute">
    <origin
      xyz="0 -0.010414 0.06155"
      rpy="1.5708 -1.5708 -3.1416" />
    <parent
      link="Link4" />
    <child
      link="Link5" />
    <axis
      xyz="0 0 -1" />
    <limit
      lower="-3.5779"
      upper="0.6283"
      effort="1"
      velocity="0.6" />
  </joint>
  <link
    name="Link6">
    <inertial>
      <origin
        xyz="5.5511E-17 5.421E-20 -0.010506"
        rpy="0 0 0" />
      <mass
        value="0.001" />
      <inertia
        ixx="0.001"
        ixy="0"
        ixz="0"
        iyy="0.001"
        iyz="0"
        izz="0.001" />
    </inertial>
    <visual>
      <origin
        xyz="0 0 0"
        rpy="0 0 0" />
      <geometry>
        <mesh
          filename="mirobot/Shaft.STL" />
      </geometry>
      <material
        name="">
        <color
          rgba="0.83 0.83 0.83 1" />
      </material>
    </visual>
    <collision>
      <origin
        xyz="0 0 0"
        rpy="0 0 0" />
      <geometry>
        <mesh
          filename="mirobot/Shaft.STL" />
      </geometry>
    </collision>
  </link>
  <joint
    name="joint6"
    type="revolute">
    <origin
      xyz="0 -0.01628 0.010525"
      rpy="-1.5708 0 0" />
    <parent
      link="Link5" />
    <child
      link="Link6" />
    <axis
      xyz="0 0 1" />
    <limit
      lower="-6.2832"
      upper="6.2832"
      effort="1"
      velocity="0.8" />
  </joint>
  <link
    name="Vacuum">
    <inertial>
      <origin
        xyz="5.5511E-17 5.421E-20 -0.010506"
        rpy="0 0 0" />
      <mass
        value="0.001" />
      <inertia
        ixx="0.001"
        ixy="0"
        ixz="0"
        iyy="0.001"
        iyz="0"
        izz="0.001" />
    </inertial>
    <visual>
      <origin
        xyz="0 0 0"
        rpy="0 0 0" />
      <geometry>
        <mesh
          filename="mirobot/Vacuum.STL" />
      </geometry>
      <material
        name="">
        <color
          rgba="0.83 0.83 0.83 1" />
      </material>
    </visual>
    <collision>
      <origin
        xyz="0 0 0"
        rpy="0 0 0" />
      <geometry>
        <mesh
          filename="mirobot/Vacuum.STL" />
      </geometry>
    </collision>
  </link>
  <joint
    name="VacuumJoint"
    type="fixed">
    <origin
      xyz="0 0 0"
      rpy="0 0 0" />
    <parent
      link="Link6" />
    <child
      link="Vacuum" />
  </joint>

  
  <!-- Transmissions for ROS Control -->
  <xacro:macro name="transmission_block" params="joint_name">
    <transmission name="tran1">
      <type>transmission_interface/SimpleTransmission</type>
      <joint name="${joint_name}">
        <hardwareInterface>hardware_interface/PositionJointInterface</hardwareInterface>
      </joint>
      <actuator name="motor1">
        <hardwareInterface>hardware_interface/PositionJointInterface</hardwareInterface>
        <mechanicalReduction>1</mechanicalReduction>
      </actuator>
    </transmission>
  </xacro:macro>
  
  <xacro:transmission_block joint_name="joint1"/>
  <xacro:transmission_block joint_name="joint2"/>
  <xacro:transmission_block joint_name="joint3"/>
  <xacro:transmission_block joint_name="joint4"/>
  <xacro:transmission_block joint_name="joint5"/>
  <xacro:transmission_block joint_name="joint6"/>
  <!-- ros_control plugin -->
  <gazebo>
    <plugin name="gazebo_ros_control" filename="libgazebo_ros_control.so">
      <robotNamespace>/mirobot</robotNamespace>
      <robotSimType>gazebo_ros_control/DefaultRobotHWSim</robotSimType>
      <legacyModeNS>true</legacyModeNS>
    </plugin>
  </gazebo>	
  <klampt world_frame="world" defaultAccMax="1.2">
    <link name="Link1" servoP="10" servoI="0" servoD="1" />
    <link name="Link2" servoP="10" servoI="0" servoD="1" />
    <link name="Link3" servoP="5" servoI="0" servoD=".5" />
    <link name="Link4" servoP="5" servoI="0" servoD=".5" />
    <link name="Link5" servoP="3" servoI="0" servoD=".3" />
    <link name="Link6" servoP="2" servoI="0" servoD=".2" />
    <noselfcollision pairs="5 7" />
  </klampt>
</robot>